Workbook

Sheet Legende
A1: CyberDrome -- Teile-Uebersicht
A2: Erzeugt aus parts/ durch tools/export_parts_table.py. Nicht von Hand pflegen, sondern neu erzeugen.
A4: Blatt | C4: Was drin steht
A5: Alle Teile | B5: Volle Tabelle aller Teile zum Filtern und Sortieren.
A6: Koerperteile | B6: Chassis: HP, Panzerung, Traglast, Ausruestungsslots.
A7: Kopfteile | B7: Sensorik: Zielwert, Sicht, Panzerung am Kopf.
A8: Fussteile | B8: Antriebe: Bewegung, Tempo, Gelaendeverhalten.
A9: Kerne | B9: Energiespeicher und Energieabgabe -- das Budget des Aufbaus.
A10: Ausruestung Waffen | B10: Alles mit Bauart „Waffe“, samt Aktionswerten.
A11: Ausruestung Sonstiges | B11: Schilde und Support-Module.
A12: Chassis & Slots | B12: Je Chassis: wie viele Ausruestungsanker, und was jeder annimmt.
A13: Kompatibilitaet | B13: Lebende Matrix: welches Ausruestungsteil an welchen Slot passt. Rechnet aus „Klasse“ und „Bauart“ -- aendert man die, aendert sich die Matrix mit.
A14: Silhouetten | B14: Wie aehnlich sich zwei Teile desselben Typs sehen. 1.00 waere ununterscheidbar; ab 0.80 bricht der Generator bei Ausruestung ab.
A16: Bestand | B16: zaehlt das Blatt „Alle Teile“ -- kommt ein Teil dazu, stimmt die Zahl von selbst
A17: Bauteiltyp | B17: Anzahl | C17: Rolle im Spiel
A18: Koerper | B18: =COUNTIF('Alle Teile'!$D$5:$D$27,A18) | C18: Chassis: HP, Panzerung, Traglast -- und die Zahl der Ausruestungsslots
A19: Kopf | B19: =COUNTIF('Alle Teile'!$D$5:$D$27,A19) | C19: Sensorik: Sicht, Zielwert, Statusresistenz
A20: Fuesse | B20: =COUNTIF('Alle Teile'!$D$5:$D$27,A20) | C20: Bewegungsreichweite, Gelaendeverhalten, Tempo
A21: Kern | B21: =COUNTIF('Alle Teile'!$D$5:$D$27,A21) | C21: Identitaet der Einheit: Energiespeicher und Energieabgabe
A22: Ausruestung | B22: =COUNTIF('Alle Teile'!$D$5:$D$27,A22) | C22: Waffen, Schilde, Support-Module -- alles, was Aktionen gewaehrt
A23: Summe | B23: =SUM(B18:B22)
A25: Spielwerte | B25: Ein DROME hat keine Grundwerte: jeder Wert ist die Summe seiner Teile (drome_build.gd)
A26: Feld in der JSON | B26: Spalte | C26: Bedeutung
A27: hp | B27: HP | C27: Strukturpunkte. Ein DROME hat keine Grundwerte -- seine Lebensleiste ist die Summe aus Chassis und Kopf.
A28: en_max | B28: EN max | C28: Energiespeicher. Bezahlt die EN-Kosten der Aktionen.
A29: en_regen | B29: EN/Zyklus | C29: Energie, die je Zyklus nachlaeuft.
A30: spd | B30: SPD | C30: Tempo auf der TICK-Leiste: so viel fuellt der DROME je Tick, bei 100 ist er am Zug. Muss im fertigen Aufbau mindestens 1 sein.
A31: mov | B31: MOV | C31: Felder je Zug. Muss im fertigen Aufbau mindestens 1 sein.
A32: atk | B32: ATK | C32: Angriffsbonus, additiv auf die Power der Aktion.
A33: def | B33: DEF | C33: Schadensminderung.
A34: weight | B34: Gewicht | C34: Zaehlt gegen die Traglast des Chassis.
A35: power_draw | B35: Energiebedarf | C35: Zaehlt gegen die Energieabgabe des Kerns.
A36: weight_capacity | B36: Traglast | C36: Nur Chassis: wie viel Gewicht der Aufbau insgesamt tragen darf.
A37: power_output | B37: Energieabgabe | C37: Nur Kern: wie viel Energiebedarf der Aufbau insgesamt haben darf.
... A43: grants_ignore_haze | B43: sieht durch Haze | C43: Haze-Felder blockieren die Sichtlinie dieses DROME nicht.
A45: Aktionswerte | B45: Schaden ist deterministisch -- kein Trefferwurf, kein Krit, keine Ausweichchance (action_data.gd)
A46: Feld in der JSON | B46: Spalte | C46: Bedeutung
A47: range_tiles | B47: Reichweite | C47: Felder bis zum Ziel.
A48: aoe_radius | B48: AoE | C48: Radius um das Ziel. 0 = nur das Ziel selbst.
A49: en_cost | B49: EN-Kosten | C49: Energie je Einsatz.
...

Sheet Alle Teile
A1: Alle Teile auf einen Blick
A2: Der volle Wertesatz in einer Tabelle -- zum Filtern und Sortieren. Zum Lesen und Vergleichen sind die Typblaetter gedacht: dort steht nur, was der jeweilige Typ auch fuehrt.
A4: Code | B4: Name | C4: Set | D4: Typ | E4: Bauart | F4: Montageklasse | G4: HP | H4: EN max | I4: EN/Zyklus | J4: SPD | K4: MOV | L4: ATK | M4: DEF | N4: Gewicht | O4: Energiebedarf | P4: Traglast | Q4: Energieabgabe | R4: Aktion | S4: Power | T4: Reichweite | U4: EN-Kosten | V4: Threat-Beitrag | W4: Tags
A5: CHS-001 | B5: Vireo Chassis | C5: RX-Vireo // Scout | D5: Koerper | G5: 60 | J5: 2 | M5: 1 | P5: 18 | V5: =G5*1+L5*6+M5*8+J5*3+K5*4+H5*0.5 | W5: light, scout
A6: CHS-002 | B6: Molok Chassis | C6: HX-Molok // Juggernaut | D6: Koerper | G6: 130 | J6: -2 | K6: -1 | M6: 5 | P6: 28 | V6: =G6*1+L6*6+M6*8+J6*3+K6*4+H6*0.5 | W6: heavy
A7: CHS-003 | B7: Nimbus Chassis | C7: AR-Nimbus // Technomant | D7: Koerper | G7: 85 | H7: 10 | M7: 2 | P7: 20 | V7: =G7*1+L7*6+M7*8+J7*3+K7*4+H7*0.5 | W7: round, mage, support
A8: CHS-004 | B8: Strix Chassis | C8: LR-Strix // Marksman | D8: Koerper | G8: 70 | J8: 1 | M8: 2 | P8: 22 | V8: =G8*1+L8*6+M8*8+J8*3+K8*4+H8*0.5 | W8: marksman, light, sniper
A9: HED-001 | B9: Vireo Sensorkopf | C9: RX-Vireo // Scout | D9: Kopf | J9: 2 | N9: 2 | O9: 2 | V9: =G9*1+L9*6+M9*8+J9*3+K9*4+H9*0.5 | W9: light, sensor
A10: HED-002 | B10: Molok Bunkerkopf | C10: HX-Molok // Juggernaut | D10: Kopf | G10: 15 | M10: 2 | N10: 4 | O10: 1 | V10: =G10*1+L10*6+M10*8+J10*3+K10*4+H10*0.5 | W10: heavy, armored
A11: HED-003 | B11: Nimbus Flachhelm | C11: AR-Nimbus // Technomant | D11: Kopf | H11: 15 | I11: 3 | N11: 2 | O11: 2 | V11: =G11*1+L11*6+M11*8+J11*3+K11*4+H11*0.5 | W11: round, mage, sensor
A12: HED-004 | B12: Strix Okularkopf | C12: LR-Strix // Marksman | D12: Kopf | L12: 4 | N12: 3 | O12: 3 | V12: =G12*1+L12*6+M12*8+J12*3+K12*4+H12*0.5 | W12: marksman, sensor, optics
A13: LEG-001 | B13: Vireo Sprintbeine | C13: RX-Vireo // Scout | D13: Fuesse | J13: 11 | K13: 4 | N13: 3 | O13: 4 | V13: =G13*1+L13*6+M13*8+J13*3+K13*4+H13*0.5 | W13: light, fast
A14: LEG-002 | B14: Molok Standbeine | C14: HX-Molok // Juggernaut | D14: Fuesse | J14: 8 | K14: 3 | M14: 2 | N14: 6 | O14: 2 | V14: =G14*1+L14*6+M14*8+J14*3+K14*4+H14*0.5 | W14: heavy, slow
A15: LEG-003 | B15: Nimbus Fahrwerk | C15: AR-Nimbus // Technomant | D15: Fuesse | J15: 14 | K15: 5 | N15: 4 | O15: 4 | V15: =G15*1+L15*6+M15*8+J15*3+K15*4+H15*0.5 | W15: wheels, round, fast
A16: LEG-004 | B16: Strix Federbeine | C16: LR-Strix // Marksman | D16: Fuesse | J16: 9 | K16: 4 | N16: 5 | O16: 4 | V16: =G16*1+L16*6+M16*8+J16*3+K16*4+H16*0.5 | W16: marksman, digitigrad
A17: COR-001 | B17: Vireo Impulskern | C17: RX-Vireo // Scout | D17: Kern | H17: 40 | I17: 8 | N17: 3 | Q17: 12 | V17: =G17*1+L17*6+M17*8+J17*3+K17*4+H17*0.5 | W17: core, energy
A18: COR-002 | B18: Molok Fusionskern | C18: HX-Molok // Juggernaut | D18: Kern | H18: 70 | I18: 12 | N18: 6 | Q18: 16 | V18: =G18*1+L18*6+M18*8+J18*3+K18*4+H18*0.5 | W18: core, fusion
A19: COR-003 | B19: Nimbus Arkankern | C19: AR-Nimbus // Technomant | D19: Kern | H19: 85 | I19: 14 | N19: 5 | Q19: 14 | V19: =G19*1+L19*6+M19*8+J19*3+K19*4+H19*0.5 | W19: core, arcane
A20: COR-004 | B20: Strix Zielrechner | C20: LR-Strix // Marksman | D20: Kern | H20: 50 | I20: 10 | L20: 2 | N20: 4 | Q20: 13 | V20: =G20*1+L20*6+M20*8+J20*3+K20*4+H20*0.5 | W20: core, optics
A21: EQP-001 | B21: Puls-Blaster | C21: RX-Vireo // Scout | D21: Ausruestung | E21: Waffe | F21: leicht | N21: 5 | O21: 3 | R21: Puls-Salve | S21: 12 | T21: 4 | V21: =G21*1+L21*6+M21*8+J21*3+K21*4+H21*0.5 | W21: weapon, ranged
A22: EQP-002 | B22: Deflektor-Schild | C22: RX-Vireo // Scout | D22: Ausruestung | E22: Schild | F22: mittel | M22: 5 | N22: 4 | O22: 2 | V22: =G22*1+L22*6+M22*8+J22*3+K22*4+H22*0.5 | W22: defense
A23: EQP-003 | B23: Belagerungskanone | C23: HX-Molok // Juggernaut | D23: Ausruestung | E23: Waffe | F23: schwer | N23: 8 | O23: 5 | R23: Belagerungsschlag | S23: 18 | T23: 6 | U23: 5 | V23: =G23*1+L23*6+M23*8+J23*3+K23*4+H23*0.5 | W23: weapon, heavy
A24: EQP-004 | B24: Drohnen-Pod | C24: HX-Molok // Juggernaut | D24: Ausruestung | E24: Support | F24: leicht | N24: 3 | O24: 4 | R24: Reparaturdrohnen | S24: -10 | T24: 3 | U24: 12 | V24: =G24*1+L24*6+M24*8+J24*3+K24*4+H24*0.5 | W24: support, shoulder
A25: EQP-005 | B25: Runenstab | C25: AR-Nimbus // Technomant | D25: Ausruestung | E25: Waffe | F25: leicht | N25: 4 | O25: 2 | R25: Runenschlag | S25: 18 | T25: 1 | V25: =G25*1+L25*6+M25*8+J25*3+K25*4+H25*0.5 | W25: weapon, arcane, round
A26: EQP-006 | B26: Orbit-Fokus | C26: AR-Nimbus // Technomant | D26: Ausruestung | E26: Support | F26: leicht | L26: 1 | N26: 3 | O26: 3 | R26: Orbit-Sog | T26: 4 | U26: 8 | V26: =G26*1+L26*6+M26*8+J26*3+K26*4+H26*0.5 | W26: support, arcane, round
A27: EQP-007 | B27: Schienen-Lanze | C27: LR-Strix // Marksman | D27: Ausruestung | E27: Waffe | F27: schwer | N27: 8 | O27: 5 | R27: Schienenschuss | S27: 16 | T27: 7 | U27: 6 | V27: =G27*1+L27*6+M27*8+J27*3+K27*4+H27*0.5 | W27: weapon, heavy, sniper

Sheet Koerperteile
A1: Koerperteile -- Chassis
A2: Das Chassis traegt alles andere: es bringt den Grossteil der HP, setzt die Traglast und bestimmt ueber seine equip_*-Anker, wie viele Ausruestungsslots der DROME ueberhaupt hat.
A4: Code | B4: Name | C4: Set | D4: Datei-Slug | E4: HP | F4: DEF | G4: SPD | H4: MOV | I4: Traglast | J4: EN max | K4: Slots | L4: Slots und ihre Regel | M4: Threat-Beitrag | N4: Silhouetten-Merkmal | O4: sagt dem Spieler | P4: Tags
A5: CHS-001 | B5: Vireo Chassis | C5: RX-Vireo // Scout | D5: scout_body | E5: 60 | F5: 1 | G5: 2 | H5: 0 | I5: 18 | J5: 0 | K5: 2 | L5: left: bis mittel right: bis mittel | M5: =E5*1+F5*8+G5*3+H5*4+J5*0.5 | N5: schlank, kantig, zweibeinig | O5: leichter Standardrahmen, zwei Arme | P5: light, scout
A6: CHS-002 | B6: Molok Chassis | C6: HX-Molok // Juggernaut | D6: jugg_body | E6: 130 | F6: 5 | G6: -2 | H6: -1 | I6: 28 | J6: 0 | K6: 3 | L6: left: bis schwer right: bis schwer shoulder: bis leicht · nur Support | M6: =E6*1+F6*8+G6*3+H6*4+J6*0.5 | N6: geduckt: Panzerschuerze, Keil-Torso, Pauldrons ueber dem Kopfsockel, Auspuffstapel | O6: schwerer Rahmen, drei Anker -- Schulter nur fuer Support | P6: heavy
A7: CHS-003 | B7: Nimbus Chassis | C7: AR-Nimbus // Technomant | D7: mage_body | E7: 85 | F7: 2 | G7: 0 | H7: 0 | I7: 20 | J7: 10 | K7: 2 | L7: left: bis mittel right: bis mittel | M7: =E7*1+F7*8+G7*3+H7*4+J7*0.5 | N7: rund, Fahrgestell statt Beinen | O7: Support-Rahmen, weiche Formensprache | P7: round, mage, support
A8: CHS-004 | B8: Strix Chassis | C8: LR-Strix // Marksman | D8: strix_body | E8: 70 | F8: 2 | G8: 1 | H8: 0 | I8: 22 | J8: 0 | K8: 1 | L8: center: bis schwer | M8: =E8*1+F8*8+G8*3+H8*4+J8*0.5 | N8: schmal und hoch, Gegengewichts-Ausleger ueber dem Kopf | O8: Ein-Slot-Rahmen, Scharfschuetze | P8: marksman, light, sniper
A10: Minimum | B10: Kennzahlen ueber die Zeilen darueber -- Formeln, keine festen Zahlen | E10: =MIN(E5:E8) | F10: =MIN(F5:F8) | G10: =MIN(G5:G8) | H10: =MIN(H5:H8) | I10: =MIN(I5:I8) | J10: =MIN(J5:J8) | K10: =MIN(K5:K8) | M10: =MIN(M5:M8)
A11: Mittel | E11: =AVERAGE(E5:E8) | F11: =AVERAGE(F5:F8) | G11: =AVERAGE(G5:G8) | H11: =AVERAGE(H5:H8) | I11: =AVERAGE(I5:I8) | J11: =AVERAGE(J5:J8) | K11: =AVERAGE(K5:K8) | M11: =AVERAGE(M5:M8)
A12: Maximum | E12: =MAX(E5:E8) | F12: =MAX(F5:F8) | G12: =MAX(G5:G8) | H12: =MAX(H5:H8) | I12: =MAX(I5:I8) | J12: =MAX(J5:J8) | K12: =MAX(K5:K8) | M12: =MAX(M5:M8)

Sheet Kopfteile
A1: Kopfteile -- Sensorik
A2: Der Kopf entscheidet, was der DROME sieht und wie genau er trifft. Nur der Molok-Bunkerkopf bringt zusaetzlich Struktur mit.
A4: Code | B4: Name | C4: Set | D4: Datei-Slug | E4: ATK | F4: DEF | G4: HP | H4: SPD | I4: EN max | J4: EN/Zyklus | K4: Gewicht | L4: Energiebedarf | M4: sieht durch Haze | N4: Threat-Beitrag | O4: Silhouetten-Merkmal | P4: sagt dem Spieler | Q4: Tags
A5: HED-001 | B5: Vireo Sensorkopf | C5: RX-Vireo // Scout | D5: scout_head | E5: 0 | F5: 0 | G5: 0 | H5: 2 | I5: 0 | J5: 0 | K5: 2 | L5: 2 | M5: ja | N5: =G5*1+E5*6+F5*8+H5*3+I5*0.5 | O5: kleiner Helm mit Visierband und Antenne | P5: Aufklaerung | Q5: light, sensor
A6: HED-002 | B6: Molok Bunkerkopf | C6: HX-Molok // Juggernaut | D6: jugg_head | E6: 0 | F6: 2 | G6: 15 | H6: 0 | I6: 0 | J6: 0 | K6: 4 | L6: 1 | M6: – | N6: =G6*1+E6*6+F6*8+H6*3+I6*0.5 | O6: wuchtiger Bunkerkopf mit Seitensensoren | P6: gepanzert, robust | Q6: heavy, armored
A7: HED-003 | B7: Nimbus Flachhelm | C7: AR-Nimbus // Technomant | D7: mage_head | E7: 0 | F7: 0 | G7: 0 | H7: 0 | I7: 15 | J7: 3 | K7: 2 | L7: 2 | M7: – | N7: =G7*1+E7*6+F7*8+H7*3+I7*0.5 | O7: flacher Helm mit weit auskragender Krempe | P7: Rundumsicht, arkan | Q7: round, mage, sensor
A8: HED-004 | B8: Strix Okularkopf | C8: LR-Strix // Marksman | D8: strix_head | E8: 4 | F8: 0 | G8: 0 | H8: 0 | I8: 0 | J8: 0 | K8: 3 | L8: 3 | M8: ja | N8: =G8*1+E8*6+F8*8+H8*3+I8*0.5 | O8: ein langes Okular statt Visierband, Rueckenfinne | P8: sieht WEIT statt viel | Q8: marksman, sensor, optics
A10: Minimum | B10: Kennzahlen ueber die Zeilen darueber -- Formeln, keine festen Zahlen | E10: =MIN(E5:E8) | F10: =MIN(F5:F8) | G10: =MIN(G5:G8) | H10: =MIN(H5:H8) | I10: =MIN(I5:I8) | J10: =MIN(J5:J8) | K10: =MIN(K5:K8) | L10: =MIN(L5:L8) | N10: =MIN(N5:N8)
A11: Mittel | E11: =AVERAGE(E5:E8) | F11: =AVERAGE(F5:F8) | G11: =AVERAGE(G5:G8) | H11: =AVERAGE(H5:H8) | I11: =AVERAGE(I5:I8) | J11: =AVERAGE(J5:J8) | K11: =AVERAGE(K5:K8) | L11: =AVERAGE(L5:L8) | N11: =AVERAGE(N5:N8)
A12: Maximum | E12: =MAX(E5:E8) | F12: =MAX(F5:F8) | G12: =MAX(G5:G8) | H12: =MAX(H5:H8) | I12: =MAX(I5:I8) | J12: =MAX(J5:J8) | K12: =MAX(K5:K8) | L12: =MAX(L5:L8) | N12: =MAX(N5:N8)

Sheet Fussteile
A1: Fussteile -- Antrieb
A2: Der Antrieb ist die eigentliche Kaufentscheidung im Gelaende: nicht MOV allein, sondern welche Felder ueberhaupt betretbar sind. Die Flags rechts sind das, was ein Antrieb kann und ein anderer nicht.
A4: Code | B4: Name | C4: Set | D4: Datei-Slug | E4: MOV | F4: SPD | G4: DEF | H4: Gewicht | I4: Energiebedarf | J4: durch Einheiten | K4: Stufen | L4: Drift egal | M4: Drift +/- | N4: Stufen billiger | O4: Threat-Beitrag | P4: Silhouetten-Merkmal | Q4: sagt dem Spieler | R4: Tags
A5: LEG-001 | B5: Vireo Sprintbeine | C5: RX-Vireo // Scout | D5: scout_feet | E5: 4 | F5: 11 | G5: 0 | H5: 3 | I5: 4 | J5: ja | K5: ja | L5: – | M5: 0 | N5: – | O5: =G5*8+F5*3+E5*4 | P5: schmaler Stand, gerade Stelzen, eine Zehe | Q5: schnell | R5: light, fast
A6: LEG-002 | B6: Molok Standbeine | C6: HX-Molok // Juggernaut | D6: jugg_feet | E6: 3 | F6: 8 | G6: 2 | H6: 6 | I6: 2 | J6: – | K6: – | L6: ja | M6: 0 | N6: – | O6: =G6*8+F6*3+E6*4 | P6: breiter Stand auf Auslegern, Hydraulikzylinder, Ferse | Q6: langsam, standfest, stuetzt Rueckstoss ab | R6: heavy, slow
A7: LEG-003 | B7: Nimbus Fahrwerk | C7: AR-Nimbus // Technomant | D7: mage_drive | E7: 5 | F7: 14 | G7: 0 | H7: 4 | I7: 4 | J7: – | K7: – | L7: – | M7: 1 | N7: – | O7: =G7*8+F7*3+E7*4 | P7: zwei grosse Raeder auf einer Achse | Q7: rollend, schnell auf Ebene | R7: wheels, round, fast
A8: LEG-004 | B8: Strix Federbeine | C8: LR-Strix // Marksman | D8: strix_feet | E8: 4 | F8: 9 | G8: 0 | H8: 5 | I8: 4 | J8: – | K8: ja | L8: – | M8: 0 | N8: ja | O8: =G8*8+F8*3+E8*4 | P8: Knick nach hinten, digitigrad | Q8: federnd, mittlere Reichweite | R8: marksman, digitigrad
A10: Minimum | B10: Kennzahlen ueber die Zeilen darueber -- Formeln, keine festen Zahlen | E10: =MIN(E5:E8) | F10: =MIN(F5:F8) | G10: =MIN(G5:G8) | H10: =MIN(H5:H8) | I10: =MIN(I5:I8) | M10: =MIN(M5:M8) | O10: =MIN(O5:O8)
A11: Mittel | E11: =AVERAGE(E5:E8) | F11: =AVERAGE(F5:F8) | G11: =AVERAGE(G5:G8) | H11: =AVERAGE(H5:H8) | I11: =AVERAGE(I5:I8) | M11: =AVERAGE(M5:M8) | O11: =AVERAGE(O5:O8)
A12: Maximum | E12: =MAX(E5:E8) | F12: =MAX(F5:F8) | G12: =MAX(G5:G8) | H12: =MAX(H5:H8) | I12: =MAX(I5:I8) | M12: =MAX(M5:M8) | O12: =MAX(O5:O8)

Sheet Kerne
A1: Kerne -- Energie
A2: Der Kern setzt zwei Grenzen: EN max deckelt, wie oft Aktionen mit EN-Kosten gehen, und die Energieabgabe deckelt, wie viel Geraet ueberhaupt angebaut werden darf. Ein Kern ist damit weniger eine Waffe als ein Budget.
A4: Code | B4: Name | C4: Set | D4: Datei-Slug | E4: EN max | F4: EN/Zyklus | G4: Energieabgabe | H4: ATK | I4: Gewicht | J4: Threat-Beitrag | K4: Silhouetten-Merkmal | L4: sagt dem Spieler | M4: Tags
A5: COR-001 | B5: Vireo Impulskern | C5: RX-Vireo // Scout | D5: scout_core | E5: 40 | F5: 8 | G5: 12 | H5: 0 | I5: 3 | J5: =H5*6+E5*0.5 | K5: Scheibe mit vier Energiestrichen | L5: Impuls | M5: core, energy
A6: COR-002 | B6: Molok Fusionskern | C6: HX-Molok // Juggernaut | D6: jugg_core | E6: 70 | F6: 12 | G6: 16 | H6: 0 | I6: 6 | J6: =H6*6+E6*0.5 | K6: grosse Scheibe mit Kreuzglut | L6: Fusion, hohe Leistung | M6: core, fusion
A7: COR-003 | B7: Nimbus Arkankern | C7: AR-Nimbus // Technomant | D7: mage_core | E7: 85 | F7: 14 | G7: 14 | H7: 0 | I7: 5 | J7: =H7*6+E7*0.5 | K7: Orb mit umlaufenden Ringen | L7: arkan | M7: core, arcane
A8: COR-004 | B8: Strix Zielrechner | C8: LR-Strix // Marksman | D8: strix_core | E8: 50 | F8: 10 | G8: 13 | H8: 2 | I8: 4 | J8: =H8*6+E8*0.5 | K8: senkrechter Leuchtspalt statt Scheibe | L8: Zielrechner, Optik | M8: core, optics
A10: Minimum | B10: Kennzahlen ueber die Zeilen darueber -- Formeln, keine festen Zahlen | E10: =MIN(E5:E8) | F10: =MIN(F5:F8) | G10: =MIN(G5:G8) | H10: =MIN(H5:H8) | I10: =MIN(I5:I8) | J10: =MIN(J5:J8)
A11: Mittel | E11: =AVERAGE(E5:E8) | F11: =AVERAGE(F5:F8) | G11: =AVERAGE(G5:G8) | H11: =AVERAGE(H5:H8) | I11: =AVERAGE(I5:I8) | J11: =AVERAGE(J5:J8)
A12: Maximum | E12: =MAX(E5:E8) | F12: =MAX(F5:F8) | G12: =MAX(G5:G8) | H12: =MAX(H5:H8) | I12: =MAX(I5:I8) | J12: =MAX(J5:J8)

Sheet Ausruestung Waffen
A1: Ausruestung -- Waffen
A2: Bauart „Waffe“. Ohne mindestens eine davon ist ein Aufbau ungueltig. Die Spalte „Power je EN“ vergleicht, was ein Schuss kostet: eine starke Waffe mit hohen EN-Kosten ist auf einem schwachen Kern weniger wert als eine schwaechere, die nichts kostet.
A4: Code | B4: Name | C4: Set | D4: Datei-Slug | E4: Montageklasse | F4: Gewicht | G4: Energiebedarf | H4: ATK | I4: DEF | J4: Aktion | K4: Zielung | L4: Power | M4: Reichweite | N4: AoE | O4: EN-Kosten | P4: Sichtlinie | Q4: Schub | R4: Power je EN | S4: Power je Gewicht | T4: Threat als staerkste Waffe | U4: Threat-Beitrag | V4: Silhouetten-Merkmal | W4: sagt dem Spieler | X4: Tags
A5: EQP-001 | B5: Puls-Blaster | C5: RX-Vireo // Scout | D5: eq_pulse_blaster | E5: leicht | F5: 5 | G5: 3 | H5: 0 | I5: 0 | J5: Puls-Salve | K5: Einzelziel | L5: 12 | M5: 4 | N5: 0 | O5: 0 | P5: ja | Q5: 0 | R5: =IF(O5=0,"kostenlos",ROUND(L5/O5,1)) | S5: =ROUND(L5/F5,1) | T5: =L5*2 | U5: =H5*6+I5*8 | V5: ein glattes Rohr, sonst nichts | W5: leicht, kurze Reichweite | X5: weapon, ranged
A6: EQP-003 | B6: Belagerungskanone | C6: HX-Molok // Juggernaut | D6: eq_siege_cannon | E6: schwer | F6: 8 | G6: 5 | H6: 0 | I6: 0 | J6: Belagerungsschlag | K6: Flaeche um das Ziel | L6: 18 | M6: 6 | N6: 1 | O6: 5 | P6: ja | Q6: 0 | R6: =IF(O6=0,"kostenlos",ROUND(L6/O6,1)) | S6: =ROUND(L6/F6,1) | T6: =L6*2 | U6: =H6*6+I6*8 | V6: Muendungsbremse mit Querfluegeln, Trommelmagazin, Abstuetzstrebe | W6: schwer, abgestuetzt -- Artillerie | X6: weapon, heavy
A7: EQP-005 | B7: Runenstab | C7: AR-Nimbus // Technomant | D7: eq_rune_staff | E7: leicht | F7: 4 | G7: 2 | H7: 0 | I7: 0 | J7: Runenschlag | K7: Einzelziel | L7: 18 | M7: 1 | N7: 0 | O7: 0 | P7: – | Q7: 0 | R7: =IF(O7=0,"kostenlos",ROUND(L7/O7,1)) | S7: =ROUND(L7/F7,1) | T7: =L7*2 | U7: =H7*6+I7*8 | V7: langer duenner Stab mit Kopfglut | W7: arkane Waffe | X7: weapon, arcane, round
A8: EQP-007 | B8: Schienen-Lanze | C8: LR-Strix // Marksman | D8: eq_rail_lance | E8: schwer | F8: 8 | G8: 5 | H8: 0 | I8: 0 | J8: Schienenschuss | K8: Einzelziel | L8: 16 | M8: 7 | N8: 0 | O8: 6 | P8: ja | Q8: 0 | R8: =IF(O8=0,"kostenlos",ROUND(L8/O8,1)) | S8: =ROUND(L8/F8,1) | T8: =L8*2 | U8: =H8*6+I8*8 | V8: ueberlanger duenner Doppellauf, Zielblock, Gabel | W8: Praezision, grosse Reichweite | X8: weapon, heavy, sniper
A10: Minimum | B10: Kennzahlen ueber die Zeilen darueber -- Formeln, keine festen Zahlen | F10: =MIN(F5:F8) | G10: =MIN(G5:G8) | H10: =MIN(H5:H8) | I10: =MIN(I5:I8) | L10: =MIN(L5:L8) | M10: =MIN(M5:M8) | N10: =MIN(N5:N8) | O10: =MIN(O5:O8) | S10: =MIN(S5:S8) | T10: =MIN(T5:T8) | U10: =MIN(U5:U8)
A11: Mittel | F11: =AVERAGE(F5:F8) | G11: =AVERAGE(G5:G8) | H11: =AVERAGE(H5:H8) | I11: =AVERAGE(I5:I8) | L11: =AVERAGE(L5:L8) | M11: =AVERAGE(M5:M8) | N11: =AVERAGE(N5:N8) | O11: =AVERAGE(O5:O8) | S11: =AVERAGE(S5:S8) | T11: =AVERAGE(T5:T8) | U11: =AVERAGE(U5:U8)
A12: Maximum | F12: =MAX(F5:F8) | G12: =MAX(G5:G8) | H12: =MAX(H5:H8) | I12: =MAX(I5:I8) | L12: =MAX(L5:L8) | M12: =MAX(M5:M8) | N12: =MAX(N5:N8) | O12: =MAX(O5:O8) | S12: =MAX(S5:S8) | T12: =MAX(T5:T8) | U12: =MAX(U5:U8)

Sheet Ausruestung Sonstiges
A1: Ausruestung -- Schild und Support
A2: Alles, was keine Waffe ist. Der Deflektor ist rein passiv (DEF, keine Aktion); die Support-Module gewaehren stattdessen eine Faehigkeit. Negative Power heisst Heilung -- ein Vorzeichen statt zweier Felder.
A4: Code | B4: Name | C4: Set | D4: Datei-Slug | E4: Bauart | F4: Montageklasse | G4: Gewicht | H4: Energiebedarf | I4: ATK | J4: DEF | K4: Aktion | L4: Zielung | M4: Power | N4: Reichweite | O4: AoE | P4: EN-Kosten | Q4: Sichtlinie | R4: Schub | S4: Wirkung | T4: Threat-Beitrag | U4: Silhouetten-Merkmal | V4: sagt dem Spieler | W4: Tags
A5: EQP-002 | B5: Deflektor-Schild | C5: RX-Vireo // Scout | D5: eq_deflector | E5: Schild | F5: mittel | G5: 4 | H5: 2 | I5: 0 | J5: 5 | K5: — | S5: =IF(K5="—","passiv",IF(M5<0,"Heilung "&ABS(M5),IF(M5=0,"kein Schaden","Schaden "&M5))) | T5: =I5*6+J5*8 | U5: flache Wand quer zur Blickrichtung | V5: Deckung | W5: defense
A6: EQP-004 | B6: Drohnen-Pod | C6: HX-Molok // Juggernaut | D6: eq_drone_pod | E6: Support | F6: leicht | G6: 3 | H6: 4 | I6: 0 | J6: 0 | K6: Reparaturdrohnen | L6: Flaeche um das Ziel | M6: -10 | N6: 3 | O6: 1 | P6: 12 | Q6: ja | R6: 0 | S6: =IF(K6="—","passiv",IF(M6<0,"Heilung "&ABS(M6),IF(M6=0,"kein Schaden","Schaden "&M6))) | T6: =I6*6+J6*8 | U6: flacher Pod auf der Schulterbruecke | V6: Support, keine Waffe | W6: support, shoulder
A7: EQP-006 | B7: Orbit-Fokus | C7: AR-Nimbus // Technomant | D7: eq_orbit_focus | E7: Support | F7: leicht | G7: 3 | H7: 3 | I7: 1 | J7: 0 | K7: Orbit-Sog | L7: Einzelziel | M7: 0 | N7: 4 | O7: 0 | P7: 8 | Q7: ja | R7: -2 | S7: =IF(K7="—","passiv",IF(M7<0,"Heilung "&ABS(M7),IF(M7=0,"kein Schaden","Schaden "&M7))) | T7: =I7*6+J7*8 | U7: schwebender Ring vor der Hand | V7: Support, arkan | W7: support, arcane, round
A9: Minimum | B9: Kennzahlen ueber die Zeilen darueber -- Formeln, keine festen Zahlen | G9: =MIN(G5:G7) | H9: =MIN(H5:H7) | I9: =MIN(I5:I7) | J9: =MIN(J5:J7) | M9: =MIN(M5:M7) | N9: =MIN(N5:N7) | O9: =MIN(O5:O7) | P9: =MIN(P5:P7) | T9: =MIN(T5:T7)
A10: Mittel | G10: =AVERAGE(G5:G7) | H10: =AVERAGE(H5:H7) | I10: =AVERAGE(I5:I7) | J10: =AVERAGE(J5:J7) | M10: =AVERAGE(M5:M7) | N10: =AVERAGE(N5:N7) | O10: =AVERAGE(O5:O7) | P10: =AVERAGE(P5:P7) | T10: =AVERAGE(T5:T7)
A11: Maximum | G11: =MAX(G5:G7) | H11: =MAX(H5:H7) | I11: =MAX(I5:I7) | J11: =MAX(J5:J7) | M11: =MAX(M5:M7) | N11: =MAX(N5:N7) | O11: =MAX(O5:O7) | P11: =MAX(P5:P7) | T11: =MAX(T5:T7)

Sheet Chassis & Slots
A1: Chassis und ihre Ausruestungsslots
A2: Die Zahl der Slots faellt aus den equip_*-Ankern des Chassis, die Regel je Slot aus seinem Feld slot_rules.
A4: Code | B4: Chassis | C4: Set | D4: Slots | E4: Slot | F4: nimmt an | G4: Anmerkung
A5: CHS-001 | B5: Vireo Chassis | C5: RX-Vireo // Scout | D5: 2 | E5: equip_left | F5: bis mittel | G5: Sprinter: keine Artillerie an einem Arm, der sechs Felder weit laufen soll.
E6: equip_right | F6: bis mittel
A7: CHS-002 | B7: Molok Chassis | C7: HX-Molok // Juggernaut | D7: 3 | E7: equip_left | F7: bis schwer
E8: equip_right | F8: bis schwer
E9: equip_shoulder | F9: bis leicht · nur Support | G9: Bruecke hinter dem Kopf: kein Gegenhalt, keine Hand. Sensorik und Drohnen ja, Schild oder schweres Geraet nein.
A10: CHS-003 | B10: Nimbus Chassis | C10: AR-Nimbus // Technomant | D10: 2 | E10: equip_left | F10: bis mittel
E11: equip_right | F11: bis mittel
A12: CHS-004 | B12: Strix Chassis | C12: LR-Strix // Marksman | D12: 1 | E12: equip_center | F12: bis schwer | G12: Der einzige Slot -- dafuer ohne Obergrenze. Ein Slot weniger als der Standard, dafuer die schwerste Waffe.

Sheet Kompatibilitaet
A1: Was passt an welchen Slot | B1: leicht | C1: mittel | D1: schwer | E1: ← Rangfolge der Montageklassen, Nachschlagereihe fuer Spalte D
A2: Lebende Matrix: die Zellen rechnen aus Klasse und Bauart. Wer in den Spalten C bis F etwas aendert, sieht sofort, was daraus folgt.
F4: Chassis | G4: Vireo Chassis | H4: Vireo Chassis | I4: Molok Chassis | J4: Molok Chassis | K4: Molok Chassis | L4: Nimbus Chassis | M4: Nimbus Chassis | N4: Strix Chassis
F5: Slot | G5: equip_left | H5: equip_right | I5: equip_left | J5: equip_right | K5: equip_shoulder | L5: equip_left | M5: equip_right | N5: equip_center
F6: nimmt an | G6: bis mittel | H6: bis mittel | I6: bis schwer | J6: bis schwer | K6: bis leicht · nur Support | L6: bis mittel | M6: bis mittel | N6: bis schwer
F7: Rang (Hilfe) | G7: 2 | H7: 2 | I7: 3 | J7: 3 | K7: 1 | L7: 2 | M7: 2 | N7: 3
F8: Bauarten (Hilfe) | G8: Waffe,Schild,Support | H8: Waffe,Schild,Support | I8: Waffe,Schild,Support | J8: Waffe,Schild,Support | K8: Support | L8: Waffe,Schild,Support | M8: Waffe,Schild,Support | N8: Waffe,Schild,Support
A9: Code | B9: Teil | C9: Klasse | D9: Rang | E9: Bauart | F9: nur an Slot | G9: left | H9: right | I9: left | J9: right | K9: shoulder | L9: left | M9: right | N9: center
A10: EQP-001 | B10: Puls-Blaster | C10: leicht | D10: =MATCH(C10,$B$1:$D$1,0) | E10: Waffe | F10: alle | G10: =IF(AND($D10<=G$7,ISNUMBER(SEARCH($E10,G$8)),OR($F10="alle",ISNUMBER(SEARCH(G$5,$F10)))),"ja","–") | H10: =IF(AND($D10<=H$7,ISNUMBER(SEARCH($E10,H$8)),OR($F10="alle",ISNUMBER(SEARCH(H$5,$F10)))),"ja","–") | I10: =IF(AND($D10<=I$7,ISNUMBER(SEARCH($E10,I$8)),OR($F10="alle",ISNUMBER(SEARCH(I$5,$F10)))),"ja","–") | J10: =IF(AND($D10<=J$7,ISNUMBER(SEARCH($E10,J$8)),OR($F10="alle",ISNUMBER(SEARCH(J$5,$F10)))),"ja","–") | K10: =IF(AND($D10<=K$7,ISNUMBER(SEARCH($E10,K$8)),OR($F10="alle",ISNUMBER(SEARCH(K$5,$F10)))),"ja","–") | L10: =IF(AND($D10<=L$7,ISNUMBER(SEARCH($E10,L$8)),OR($F10="alle",ISNUMBER(SEARCH(L$5,$F10)))),"ja","–") | M10: =IF(AND($D10<=M$7,ISNUMBER(SEARCH($E10,M$8)),OR($F10="alle",ISNUMBER(SEARCH(M$5,$F10)))),"ja","–") | N10: =IF(AND($D10<=N$7,ISNUMBER(SEARCH($E10,N$8)),OR($F10="alle",ISNUMBER(SEARCH(N$5,$F10)))),"ja","–")
A11: EQP-002 | B11: Deflektor-Schild | C11: mittel | D11: =MATCH(C11,$B$1:$D$1,0) | E11: Schild | F11: alle | G11: =IF(AND($D11<=G$7,ISNUMBER(SEARCH($E11,G$8)),OR($F11="alle",ISNUMBER(SEARCH(G$5,$F11)))),"ja","–") | H11: =IF(AND($D11<=H$7,ISNUMBER(SEARCH($E11,H$8)),OR($F11="alle",ISNUMBER(SEARCH(H$5,$F11)))),"ja","–") | I11: =IF(AND($D11<=I$7,ISNUMBER(SEARCH($E11,I$8)),OR($F11="alle",ISNUMBER(SEARCH(I$5,$F11)))),"ja","–") | J11: =IF(AND($D11<=J$7,ISNUMBER(SEARCH($E11,J$8)),OR($F11="alle",ISNUMBER(SEARCH(J$5,$F11)))),"ja","–") | K11: =IF(AND($D11<=K$7,ISNUMBER(SEARCH($E11,K$8)),OR($F11="alle",ISNUMBER(SEARCH(K$5,$F11)))),"ja","–") | L11: =IF(AND($D11<=L$7,ISNUMBER(SEARCH($E11,L$8)),OR($F11="alle",ISNUMBER(SEARCH(L$5,$F11)))),"ja","–") | M11: =IF(AND($D11<=M$7,ISNUMBER(SEARCH($E11,M$8)),OR($F11="alle",ISNUMBER(SEARCH(M$5,$F11)))),"ja","–") | N11: =IF(AND($D11<=N$7,ISNUMBER(SEARCH($E11,N$8)),OR($F11="alle",ISNUMBER(SEARCH(N$5,$F11)))),"ja","–")
A12: EQP-003 | B12: Belagerungskanone | C12: schwer | D12: =MATCH(C12,$B$1:$D$1,0) | E12: Waffe | F12: alle | G12: =IF(AND($D12<=G$7,ISNUMBER(SEARCH($E12,G$8)),OR($F12="alle",ISNUMBER(SEARCH(G$5,$F12)))),"ja","–") | H12: =IF(AND($D12<=H$7,ISNUMBER(SEARCH($E12,H$8)),OR($F12="alle",ISNUMBER(SEARCH(H$5,$F12)))),"ja","–") | I12: =IF(AND($D12<=I$7,ISNUMBER(SEARCH($E12,I$8)),OR($F12="alle",ISNUMBER(SEARCH(I$5,$F12)))),"ja","–") | J12: =IF(AND($D12<=J$7,ISNUMBER(SEARCH($E12,J$8)),OR($F12="alle",ISNUMBER(SEARCH(J$5,$F12)))),"ja","–") | K12: =IF(AND($D12<=K$7,ISNUMBER(SEARCH($E12,K$8)),OR($F12="alle",ISNUMBER(SEARCH(K$5,$F12)))),"ja","–") | L12: =IF(AND($D12<=L$7,ISNUMBER(SEARCH($E12,L$8)),OR($F12="alle",ISNUMBER(SEARCH(L$5,$F12)))),"ja","–") | M12: =IF(AND($D12<=M$7,ISNUMBER(SEARCH($E12,M$8)),OR($F12="alle",ISNUMBER(SEARCH(M$5,$F12)))),"ja","–") | N12: =IF(AND($D12<=N$7,ISNUMBER(SEARCH($E12,N$8)),OR($F12="alle",ISNUMBER(SEARCH(N$5,$F12)))),"ja","–")
A13: EQP-004 | B13: Drohnen-Pod | C13: leicht | D13: =MATCH(C13,$B$1:$D$1,0) | E13: Support | F13: equip_shoulder | G13: =IF(AND($D13<=G$7,ISNUMBER(SEARCH($E13,G$8)),OR($F13="alle",ISNUMBER(SEARCH(G$5,$F13)))),"ja","–") | H13: =IF(AND($D13<=H$7,ISNUMBER(SEARCH($E13,H$8)),OR($F13="alle",ISNUMBER(SEARCH(H$5,$F13)))),"ja","–") | I13: =IF(AND($D13<=I$7,ISNUMBER(SEARCH($E13,I$8)),OR($F13="alle",ISNUMBER(SEARCH(I$5,$F13)))),"ja","–") | J13: =IF(AND($D13<=J$7,ISNUMBER(SEARCH($E13,J$8)),OR($F13="alle",ISNUMBER(SEARCH(J$5,$F13)))),"ja","–") | K13: =IF(AND($D13<=K$7,ISNUMBER(SEARCH($E13,K$8)),OR($F13="alle",ISNUMBER(SEARCH(K$5,$F13)))),"ja","–") | L13: =IF(AND($D13<=L$7,ISNUMBER(SEARCH($E13,L$8)),OR($F13="alle",ISNUMBER(SEARCH(L$5,$F13)))),"ja","–") | M13: =IF(AND($D13<=M$7,ISNUMBER(SEARCH($E13,M$8)),OR($F13="alle",ISNUMBER(SEARCH(M$5,$F13)))),"ja","–") | N13: =IF(AND($D13<=N$7,ISNUMBER(SEARCH($E13,N$8)),OR($F13="alle",ISNUMBER(SEARCH(N$5,$F13)))),"ja","–")
A14: EQP-005 | B14: Runenstab | C14: leicht | D14: =MATCH(C14,$B$1:$D$1,0) | E14: Waffe | F14: alle | G14: =IF(AND($D14<=G$7,ISNUMBER(SEARCH($E14,G$8)),OR($F14="alle",ISNUMBER(SEARCH(G$5,$F14)))),"ja","–") | H14: =IF(AND($D14<=H$7,ISNUMBER(SEARCH($E14,H$8)),OR($F14="alle",ISNUMBER(SEARCH(H$5,$F14)))),"ja","–") | I14: =IF(AND($D14<=I$7,ISNUMBER(SEARCH($E14,I$8)),OR($F14="alle",ISNUMBER(SEARCH(I$5,$F14)))),"ja","–") | J14: =IF(AND($D14<=J$7,ISNUMBER(SEARCH($E14,J$8)),OR($F14="alle",ISNUMBER(SEARCH(J$5,$F14)))),"ja","–") | K14: =IF(AND($D14<=K$7,ISNUMBER(SEARCH($E14,K$8)),OR($F14="alle",ISNUMBER(SEARCH(K$5,$F14)))),"ja","–") | L14: =IF(AND($D14<=L$7,ISNUMBER(SEARCH($E14,L$8)),OR($F14="alle",ISNUMBER(SEARCH(L$5,$F14)))),"ja","–") | M14: =IF(AND($D14<=M$7,ISNUMBER(SEARCH($E14,M$8)),OR($F14="alle",ISNUMBER(SEARCH(M$5,$F14)))),"ja","–") | N14: =IF(AND($D14<=N$7,ISNUMBER(SEARCH($E14,N$8)),OR($F14="alle",ISNUMBER(SEARCH(N$5,$F14)))),"ja","–")
A15: EQP-006 | B15: Orbit-Fokus | C15: leicht | D15: =MATCH(C15,$B$1:$D$1,0) | E15: Support | F15: alle | G15: =IF(AND($D15<=G$7,ISNUMBER(SEARCH($E15,G$8)),OR($F15="alle",ISNUMBER(SEARCH(G$5,$F15)))),"ja","–") | H15: =IF(AND($D15<=H$7,ISNUMBER(SEARCH($E15,H$8)),OR($F15="alle",ISNUMBER(SEARCH(H$5,$F15)))),"ja","–") | I15: =IF(AND($D15<=I$7,ISNUMBER(SEARCH($E15,I$8)),OR($F15="alle",ISNUMBER(SEARCH(I$5,$F15)))),"ja","–") | J15: =IF(AND($D15<=J$7,ISNUMBER(SEARCH($E15,J$8)),OR($F15="alle",ISNUMBER(SEARCH(J$5,$F15)))),"ja","–") | K15: =IF(AND($D15<=K$7,ISNUMBER(SEARCH($E15,K$8)),OR($F15="alle",ISNUMBER(SEARCH(K$5,$F15)))),"ja","–") | L15: =IF(AND($D15<=L$7,ISNUMBER(SEARCH($E15,L$8)),OR($F15="alle",ISNUMBER(SEARCH(L$5,$F15)))),"ja","–") | M15: =IF(AND($D15<=M$7,ISNUMBER(SEARCH($E15,M$8)),OR($F15="alle",ISNUMBER(SEARCH(M$5,$F15)))),"ja","–") | N15: =IF(AND($D15<=N$7,ISNUMBER(SEARCH($E15,N$8)),OR($F15="alle",ISNUMBER(SEARCH(N$5,$F15)))),"ja","–")
A16: EQP-007 | B16: Schienen-Lanze | C16: schwer | D16: =MATCH(C16,$B$1:$D$1,0) | E16: Waffe | F16: alle | G16: =IF(AND($D16<=G$7,ISNUMBER(SEARCH($E16,G$8)),OR($F16="alle",ISNUMBER(SEARCH(G$5,$F16)))),"ja","–") | H16: =IF(AND($D16<=H$7,ISNUMBER(SEARCH($E16,H$8)),OR($F16="alle",ISNUMBER(SEARCH(H$5,$F16)))),"ja","–") | I16: =IF(AND($D16<=I$7,ISNUMBER(SEARCH($E16,I$8)),OR($F16="alle",ISNUMBER(SEARCH(I$5,$F16)))),"ja","–") | J16: =IF(AND($D16<=J$7,ISNUMBER(SEARCH($E16,J$8)),OR($F16="alle",ISNUMBER(SEARCH(J$5,$F16)))),"ja","–") | K16: =IF(AND($D16<=K$7,ISNUMBER(SEARCH($E16,K$8)),OR($F16="alle",ISNUMBER(SEARCH(K$5,$F16)))),"ja","–") | L16: =IF(AND($D16<=L$7,ISNUMBER(SEARCH($E16,L$8)),OR($F16="alle",ISNUMBER(SEARCH(L$5,$F16)))),"ja","–") | M16: =IF(AND($D16<=M$7,ISNUMBER(SEARCH($E16,M$8)),OR($F16="alle",ISNUMBER(SEARCH(M$5,$F16)))),"ja","–") | N16: =IF(AND($D16<=N$7,ISNUMBER(SEARCH($E16,N$8)),OR($F16="alle",ISNUMBER(SEARCH(N$5,$F16)))),"ja","–")

Sheet Silhouetten
A1: Silhouetten-Abstand
A2: 1.00 hiesse ununterscheidbar. Bei AUSRUESTUNG ist 0.85 eine harte Grenze -- dort bricht der Generator ab, weil der Spieler an der Waffe ihre Rolle abliest. Bei RAHMENTEILEN gibt es KEINE Grenze und kein Urteil: das Mass saettigt dort, jedes gedrungene Teil wird normiert zum selben Klumpen. Brauchbar ist nur die Reihenfolge -- welches Paar liegt am engsten. Ob die Formen wirklich verschieden sind, sagt das Auge.
A4: Typ | B4: Teil A | C4: Teil B | D4: Abstand | E4: Bewertung
A5: Koerper | B5: CHS-001 Vireo Chassis | C5: CHS-002 Molok Chassis | D5: 0.85 | E5: engstes Paar dieses Typs
A6: Koerper | B6: CHS-002 Molok Chassis | C6: CHS-003 Nimbus Chassis | D6: 0.78
A7: Koerper | B7: CHS-001 Vireo Chassis | C7: CHS-003 Nimbus Chassis | D7: 0.76
A8: Kopf | B8: HED-002 Molok Bunkerkopf | C8: HED-003 Nimbus Flachhelm | D8: 0.88 | E8: engstes Paar dieses Typs
A9: Kopf | B9: HED-001 Vireo Sensorkopf | C9: HED-002 Molok Bunkerkopf | D9: 0.79
A10: Kopf | B10: HED-001 Vireo Sensorkopf | C10: HED-003 Nimbus Flachhelm | D10: 0.74
A11: Fuesse | B11: LEG-001 Vireo Sprintbeine | C11: LEG-004 Strix Federbeine | D11: 0.66 | E11: engstes Paar dieses Typs
A12: Fuesse | B12: LEG-001 Vireo Sprintbeine | C12: LEG-002 Molok Standbeine | D12: 0.56
A13: Fuesse | B13: LEG-002 Molok Standbeine | C13: LEG-003 Nimbus Fahrwerk | D13: 0.56
A14: Kern | B14: COR-002 Molok Fusionskern | C14: COR-003 Nimbus Arkankern | D14: 0.82 | E14: engstes Paar dieses Typs
A15: Kern | B15: COR-001 Vireo Impulskern | C15: COR-002 Molok Fusionskern | D15: 0.81
A16: Kern | B16: COR-001 Vireo Impulskern | C16: COR-003 Nimbus Arkankern | D16: 0.78
A17: Ausruestung | B17: EQP-001 Puls-Blaster | C17: EQP-003 Belagerungskanone | D17: 0.66 | E17: unterscheidbar
A18: Ausruestung | B18: EQP-001 Puls-Blaster | C18: EQP-004 Drohnen-Pod | D18: 0.61 | E18: unterscheidbar
A19: Ausruestung | B19: EQP-003 Belagerungskanone | C19: EQP-007 Schienen-Lanze | D19: 0.61 | E19: unterscheidbar
A21: Pruefstein: die erste Belagerungskanone (ein Blaster mit groesseren Zahlen) liegt bei 0.91 -- genau der Fall, den die Regel verbietet.
